Workbook
Name CarTypeList: Masters!$D$5:$D$11
Name EST_CAR: Estimate!$C$9
Name EST_CUST: Estimate!$C$7
Name EST_DATE: Estimate!$E$6
Name EST_KMS: Estimate!$C$8
Name EST_PLAN: Estimate!$B$11
Name EST_REG: Estimate!$E$8
Name LI_Amounts: 'Line Items'!$D$6:$P$31
Name LI_ColKey: 'Line Items'!$D$4:$P$4
Name LI_Desc: 'Line Items'!$C$6:$C$31
Name LI_Key: 'Line Items'!$Q$6:$Q$31
Name LitCarType: Masters!$B$32:$B$38
Name LitFull: Masters!$G$32:$G$38
Name LitRefresh: Masters!$F$32:$F$38
Name OilGradeCol: Masters!$B$25:$B$27
Name OilGradeList: Masters!$G$5:$G$7
Name OilName: Masters!$D$25:$D$27
Name OilRate: Masters!$H$25:$H$27
Name PayModeList: Masters!$B$16:$B$20
Name PkgKey: Masters!$K$43:$K$107
Name PkgVal: Masters!$H$43:$H$107
Name PlanList: Masters!$B$5:$B$9
Name WordsTable: Ref!$A$1:$A$100

Sheet Estimate
B2: EXPRESS AUTOCARE
B3: Multi-Brand Car Service Center
B4: Shop No. 6, Tycoon Sapphire, Nr. Godrej Hill Dmart, Khadakpada, Kalyan (West) | Mob: 99 75 68 72 80
B6: ESTIMATE | D6: Date: | E6: =TODAY() -> 46302
B7: Customer Name: Pranav Shroff | C7: Fuel Type: Petrol
B8: Car Model: Hyundai Xcent | C8: KMs: 56518
B9: Regn No:MH05DS4417
B10: Service Plan | C10: Car Type
B11: EA 360 | C11: Prem. Hatch / Sedan / Compact SUV
B12: Oil Grade | C12: Payment Mode
B13: Fully-Synthetic | C13: Cash
B15: Item Description | C15: Qty | D15: Rate | E15: Amount
B16: =INDEX(OilName,MATCH($B$13,OilGradeCol,0)) -> Mobil Super 3000 5W-30 Fully Synthetic Engine Oil | C16: 3.5 | D16: =INDEX(OilRate,MATCH($B$13,OilGradeCol,0)) -> 875 | E16: =C16*D16 -> 3062.5
B17: =IF(1<=$H$17,IFERROR(INDEX(LI_Desc,MATCH($B$11&"|"&1,LI_Key,0)),""),IF(1=$H$17+2+1,$B$11&" Maintenance Service (Labour)",IF(1=$H$17+2+2,$B$11&" — Package Total",""))) -> Oil Filter | C17: =IF(1<=$H$17,1,"") -> 1 | D17: 140 | E17: =IF(1<=$H$17+2,IF(AND(C17="",D17=""),"",IF(C17="",1,N(C17))*N(D17)),IF(1=$H$17+2+1,$H$21,IF(1=$H$17+2+2,$H$19,""))) -> 140 | G17: =IF(1<=$H$17+2,N(E17),0) -> 140 | H17: =SUMPRODUCT((LEFT(LI_Key,LEN($B$11)+1)=$B$11&"|")*1) -> 8
B18: =IF(2<=$H$17,IFERROR(INDEX(LI_Desc,MATCH($B$11&"|"&2,LI_Key,0)),""),IF(2=$H$17+2+1,$B$11&" Maintenance Service (Labour)",IF(2=$H$17+2+2,$B$11&" — Package Total",""))) -> EA Care Treatment | C18: =IF(2<=$H$17,1,"") -> 1 | D18: 799 | E18: =IF(2<=$H$17+2,IF(AND(C18="",D18=""),"",IF(C18="",1,N(C18))*N(D18)),IF(2=$H$17+2+1,$H$21,IF(2=$H$17+2+2,$H$19,""))) -> 799 | G18: =IF(2<=$H$17+2,N(E18),0) -> 799 | H18: =IFERROR(MATCH($C$11&"|"&$B$13,LI_ColKey,0),0) -> 4
B19: =IF(3<=$H$17,IFERROR(INDEX(LI_Desc,MATCH($B$11&"|"&3,LI_Key,0)),""),IF(3=$H$17+2+1,$B$11&" Maintenance Service (Labour)",IF(3=$H$17+2+2,$B$11&" — Package Total",""))) -> EA Service Kit (Consumables & Lubricants Top-up) | C19: =IF(3<=$H$17,1,"") -> 1 | D19: 699 | E19: =IF(3<=$H$17+2,IF(AND(C19="",D19=""),"",IF(C19="",1,N(C19))*N(D19)),IF(3=$H$17+2+1,$H$21,IF(3=$H$17+2+2,$H$19,""))) -> 699 | G19: =IF(3<=$H$17+2,N(E19),0) -> 699 | H19: =IFERROR(INDEX(PkgVal,MATCH($B$11&"|"&$C$11&"|"&$B$13,PkgKey,0)),0) -> 9575
B20: =IF(4<=$H$17,IFERROR(INDEX(LI_Desc,MATCH($B$11&"|"&4,LI_Key,0)),""),IF(4=$H$17+2+1,$B$11&" Maintenance Service",IF(4=$H$17+2+2,$B$11&" — Package Total",""))) -> Air Filter | C20: =IF(4<=$H$17,1,"") -> 1 | D20: 350 | E20: =IF(4<=$H$17+2,IF(AND(C20="",D20=""),"",IF(C20="",1,N(C20))*N(D20)),IF(4=$H$17+2+1,$H$21,IF(4=$H$17+2+2,$H$19,""))) -> 350 | G20: =IF(4<=$H$17+2,N(E20),0) -> 350 | H20: =SUM(G17:G27) -> 4311
B21: =IF(5<=$H$17,IFERROR(INDEX(LI_Desc,MATCH($B$11&"|"&5,LI_Key,0)),""),IF(5=$H$17+2+1,$B$11&" Maintenance Service (Labour)",IF(5=$H$17+2+2,$B$11&" — Package Total",""))) -> AC Filter | C21: =IF(5<=$H$17,1,"") -> 1 | D21: 425 | E21: =IF(5<=$H$17+2,IF(AND(C21="",D21=""),"",IF(C21="",1,N(C21))*N(D21)),IF(5=$H$17+2+1,$H$21,IF(5=$H$17+2+2,$H$19,""))) -> 425 | G21: =IF(5<=$H$17+2,N(E21),0) -> 425 | H21: =$H$19-E16-$H$20 -> 2201.5
B22: =IF(7<=$H$17,IFERROR(INDEX(LI_Desc,MATCH($B$11&"|"&7,LI_Key,0)),""),IF(7=$H$17+2+1,$B$11&" Maintenance Service",IF(7=$H$17+2+2,$B$11&" — Package Total",""))) -> Brake Service, Calliper & Drum Lining Adjustment | C22: =IF(7<=$H$17,1,"") -> 1 | D22: 1449 | E22: =IF(7<=$H$17+2,IF(AND(C22="",D22=""),"",IF(C22="",1,N(C22))*N(D22)),IF(7=$H$17+2+1,$H$21,IF(7=$H$17+2+2,$H$19,""))) -> 1449 | G22: =IF(7<=$H$17+2,N(E22),0) -> 1449
B23: =IF(8<=$H$17,IFERROR(INDEX(LI_Desc,MATCH($B$11&"|"&8,LI_Key,0)),""),IF(8=$H$17+2+1,$B$11&" Maintenance Service (Labour)",IF(8=$H$17+2+2,$B$11&" — Package Total",""))) -> Car Wash | C23: =IF(8<=$H$17,1,"") -> 1 | D23: 449 | E23: =IF(8<=$H$17+2,IF(AND(C23="",D23=""),"",IF(C23="",1,N(C23))*N(D23)),IF(8=$H$17+2+1,$H$21,IF(8=$H$17+2+2,$H$19,""))) -> 449 | G23: =IF(8<=$H$17+2,N(E23),0) -> 449
B24: =IF(11<=$H$17,IFERROR(INDEX(LI_Desc,MATCH($B$11&"|"&11,LI_Key,0)),""),IF(11=$H$17+2+1,$B$11&" Maintenance Service",IF(11=$H$17+2+2,$B$11&" — Plan Total",""))) -> EA 360 Maintenance Service | C24: =IF(11<=$H$17,1,"") | D24: =IF(11<=$H$17,IFERROR(INDEX(LI_Amounts,MATCH($B$11&"|"&11,LI_Key,0),$H$18),""),IF(11=$H$17+2+1,E24,"")) -> 2201.5 | E24: =IF(11<=$H$17+2,IF(AND(C24="",D24=""),"",IF(C24="",1,N(C24))*N(D24)),IF(11=$H$17+2+1,$H$21,IF(11=$H$17+2+2,$H$19,""))) -> 2201.5 | G24: =IF(11<=$H$17+2,N(E24),0) -> 0
B25: =IF(12<=$H$17,IFERROR(INDEX(LI_Desc,MATCH($B$11&"|"&12,LI_Key,0)),""),IF(12=$H$17+2+1,$B$11&" Maintenance Service (Labour)",IF(12=$H$17+2+2,$B$11&" — Package Total",""))) -> EA 360 — Package Total | C25: =IF(12<=$H$17,1,"") | D25: =IF(12<=$H$17,IFERROR(INDEX(LI_Amounts,MATCH($B$11&"|"&12,LI_Key,0),$H$18),""),IF(12=$H$17+2+1,E25,"")) | E25: =IF(12<=$H$17+2,IF(AND(C25="",D25=""),"",IF(C25="",1,N(C25))*N(D25)),IF(12=$H$17+2+1,$H$21,IF(12=$H$17+2+2,$H$19,""))) -> 9575 | G25: =IF(12<=$H$17+2,N(E25),0) -> 0
B26: =IF(13<=$H$17,IFERROR(INDEX(LI_Desc,MATCH($B$11&"|"&13,LI_Key,0)),""),IF(13=$H$17+2+1,$B$11&" Maintenance Service",IF(13=$H$17+2+2,$B$11&" — Package Total",""))) | C26: =IF(13<=$H$17,1,"") | D26: =IF(13<=$H$17,IFERROR(INDEX(LI_Amounts,MATCH($B$11&"|"&13,LI_Key,0),$H$18),""),IF(13=$H$17+2+1,E26,"")) | E26: =IF(13<=$H$17+2,IF(AND(C26="",D26=""),"",IF(C26="",1,N(C26))*N(D26)),IF(13=$H$17+2+1,$H$21,IF(13=$H$17+2+2,$H$19,""))) | G26: =IF(13<=$H$17+2,N(E26),0) -> 0
B27: =IF(14<=$H$17,IFERROR(INDEX(LI_Desc,MATCH($B$11&"|"&14,LI_Key,0)),""),IF(14=$H$17+2+1,$B$11&" Maintenance Service (Labour)",IF(14=$H$17+2+2,$B$11&" — Package Total",""))) | C27: =IF(14<=$H$17,1,"") | D27: =IF(14<=$H$17,IFERROR(INDEX(LI_Amounts,MATCH($B$11&"|"&14,LI_Key,0),$H$18),""),IF(14=$H$17+2+1,E27,"")) | E27: =IF(14<=$H$17+2,IF(AND(C27="",D27=""),"",IF(C27="",1,N(C27))*N(D27)),IF(14=$H$17+2+1,$H$21,IF(14=$H$17+2+2,$H$19,""))) | G27: =IF(14<=$H$17+2,N(E27),0) -> 0
B29: ADDITIONAL PARTS & LABOUR — extra work over & above the package
B30: Description | C30: Qty | D30: Rate | E30: Amount
B31: Fog Lamp Blub LHS | C31: 1 | D31: 375 | E31: =IF(D31="","",IF(C31="",1,N(C31))*N(D31)) -> 375
B32: Wiper Blade Set | C32: 1 | D32: 550 | E32: =IF(D32="","",IF(C32="",1,N(C32))*N(D32)) -> 550
B33: Throttle Body Service | C33: 1 | D33: 1770 | E33: =IF(D33="","",IF(C33="",1,N(C33))*N(D33)) -> 1770
E34: =IF(D34="","",IF(C34="",1,N(C34))*N(D34))
E35: =IF(D35="","",IF(C35="",1,N(C35))*N(D35))
E36: =IF(D36="","",IF(C36="",1,N(C36))*N(D36))
E37: =IF(D37="","",IF(C37="",1,N(C37))*N(D37))
E38: =IF(D38="","",IF(C38="",1,N(C38))*N(D38))
B40: Service Plan Total | E40: =$H$19 -> 9575
E41: =ROUND($H$19*C41,0) -> 0
E42: 0
B43: Additional Jobs Total | E43: =SUM(E31:E38) -> 2695
E44: =ROUND(E43*C44,0) -> 0
E45: 0
...

Sheet EA 360 Report
B2: EXPRESS AUTOCARE
B3: EA 360 Service Report • 75 Activity Points Carried Out
B4: Shop No. 6, Tycoon Sapphire, Nr. Godrej Hill Dmart, Khadakpada, Kalyan (West) | Mob: 99 75 68 72 80
B6: ="EA 360 Service Report" -> EA 360 Service Report | E6: ="Date: "&TEXT(EST_DATE,"dd-mmm-yyyy") -> Date: 07-Oct-2026
B7: =Estimate!B7 -> Customer Name: Pranav Shroff
B8: =Estimate!B8 -> Car Model: Hyundai Xcent | E8: =Estimate!C8 -> KMs: 56518
B9: =Estimate!B9 -> Regn No:MH05DS4417
B11: Engine & Fluids • 24 activities
B12: 1. Drain old engine oil completely | C12: ✓ | D12: 2. Inspect drain plug & washer | E12: ✓ | F12: 3. Replace drain plug washer | G12: ✓
B13: 4. Replace oil filter | C13: ✓ | D13: 5. Replace engine oil | E13: ✓ | F13: 6. Replace air filter element | G13: ✓
B14: 7. Inspect air filter housing & seal | C14: ✓ | D14: 8. Clean spark plugs | E14: ✓ | F14: 9. Check & adjust spark plug electrode gap | G14: ✓
B15: 10. Top up brake fluid | C15: ✓ | D15: 11. Top up clutch fluid (if applicable) | E15: ✓ | F15: 12. Top up power steering fluid (if applicable) | G15: ✓
B16: 13. Top up gear oil (if required) | C16: ✓ | D16: 14. Top up coolant | E16: ✓ | F16: 15. Top up battery distilled water | G16: ✓
B17: 16. Clean battery terminals | C17: ✓ | D17: 17. Battery load testing | E17: ✓ | F17: 18. Apply battery terminal coating | G17: ✓
B18: 19. Top up wiper washer fluid | C18: ✓ | D18: 20. Align wiper water nozzles | E18: ✓ | F18: 21. Check all radiator hoses | G18: ✓
B19: 22. Check drive belts for cracks | C19: ✓ | D19: 23. Adjust belt tensioner if needed | E19: ✓ | F19: 24. Check & adjust clutch play | G19: ✓
B20: Cabin, Lights & Electricals • 14 activities
B21: 1. Check all glass winder operations | C21: ✓ | D21: 2. Lubricate window run channels | E21: ✓ | F21: 3. Replace cabin AC filter | G21: ✓
B22: 4. Check AC cooling performance | C22: ✓ | D22: 5. Inspect all front lights | E22: ✓ | F22: 6. Inspect all rear lights & indicators | G22: ✓
B23: 7. Check internal lights | C23: ✓ | D23: 8. Test all power switches | E23: ✓ | F23: 9. Anti-squeak spray on hinges | G23: ✓
B24: 10. Check door locks operation | C24: ✓ | D24: 11. Lubricate all door locks | E24: ✓ | F24: 12. Lubricate glass run channels | G24: ✓
B25: 13. Onboard diagnostics scanning | C25: ✓ | D25: 14. Reset service light | E25: ✓
B26: Suspension, Wheels & Brakes • 24 activities
B27: 1. Grease all wheel nuts & bolts | C27: ✓ | D27: 2. Clean front brake pads | E27: ✓ | F27: 3. Lubricate front caliper pins | G27: ✓
B28: 4. Clean rear brake pads / liners | C28: ✓ | D28: 5. Lubricate rear caliper pins | E28: ✓ | F28: 6. Air bleed brake fluid lines | G28: ✓
B29: 7. Adjust hand brake | C29: ✓ | D29: 8. Check front wheel bearings | E29: ✓ | F29: 9. Check rear wheel bearings | G29: ✓
B30: 10. Inspect steering rack & linkages | C30: ✓ | D30: 11. Check ball joints & boots | E30: ✓ | F30: 12. Inspect front shock absorbers | G30: ✓
B31: 13. Inspect rear shock absorbers | C31: ✓ | D31: 14. Re-torque chassis nuts & bolts | E31: ✓ | F31: 15. Check all tyres for damage | G31: ✓
B32: 16. Inspect all wheel rims | C32: ✓ | D32: 17. Inspect wheel arches | E32: ✓ | F32: 18. Inspect entire underbody | G32: ✓
B33: 19. Tyre cross rotation | C33: ✓ | D33: 20. Final wheel nuts torque | E33: ✓ | F33: 21. Check & inflate all tyre pressures | G33: ✓
B34: 22. Wheel alignment | C34: ✓ | D34: 23. Wheel balancing | E34: ✓ | F34: 24. Add wheel balancing weights | G34: ✓
B35: Road Test & Final Checks • 4 activities
B36: 1. Trial drive - engine performance | C36: ✓ | D36: 2. Trial drive - brake performance | E36: ✓ | F36: 3. Trial drive - suspension check | G36: ✓
B37: 4. Final inspection post trial | C37: ✓
B38: Cleaning & Report • 9 activities
B39: 1. Vacuum interior | C39: ✓ | D39: 2. Dashboard & door trims wipe | E39: ✓ | F39: 3. Dashboard & door trims polish | G39: ✓
B40: 4. Clean interior floor mats | C40: ✓ | D40: 5. Body wash | E40: ✓ | F40: 6. Grease all door hinges | G40: ✓
B41: 7. Grease boot hinges | C41: ✓ | D41: 8. AC disinfectant spray in vents | E41: ✓ | F41: 9. Comprehensive service report | G41: ✓
B43: ADDITIONAL JOBS DONE (charges: refer to Estimate)
B44: =IF(Estimate!B31="","",1) -> 1 | C44: =IF(Estimate!B31="","",Estimate!B31) -> Fog Lamp Blub LHS
...

Sheet EA Elite Report
B2: EXPRESS AUTOCARE
B3: EA Elite Service Report • 85 Activity Points Carried Out
B4: Shop No. 6, Tycoon Sapphire, Nr. Godrej Hill Dmart, Khadakpada, Kalyan (West) | Mob: 99 75 68 72 80
B6: ="EA Elite Service Report" -> EA Elite Service Report | E6: ="Date: "&TEXT(EST_DATE,"dd-mmm-yyyy") -> Date: 07-Oct-2026
B7: =Estimate!B7 -> Customer Name: Pranav Shroff
B8: =Estimate!B8 -> Car Model: Hyundai Xcent | E8: =Estimate!C8 -> KMs: 56518
B9: =Estimate!B9 -> Regn No:MH05DS4417
B11: Engine & Fluids • 24 activities
B12: 1. Drain old engine oil completely | C12: ✓ | D12: 2. Inspect drain plug & washer | E12: ✓ | F12: 3. Replace drain plug washer | G12: ✓
B13: 4. Replace oil filter | C13: ✓ | D13: 5. Replace engine oil | E13: ✓ | F13: 6. Replace air filter element | G13: ✓
B14: 7. Inspect air filter housing & seal | C14: ✓ | D14: 8. Clean spark plugs | E14: ✓ | F14: 9. Check & adjust spark plug electrode gap | G14: ✓
B15: 10. Top up brake fluid | C15: ✓ | D15: 11. Top up clutch fluid (if applicable) | E15: ✓ | F15: 12. Top up power steering fluid (if applicable) | G15: ✓
B16: 13. Top up gear oil (if required) | C16: ✓ | D16: 14. Top up coolant | E16: ✓ | F16: 15. Top up battery distilled water | G16: ✓
B17: 16. Clean battery terminals | C17: ✓ | D17: 17. Battery load testing | E17: ✓ | F17: 18. Apply battery terminal coating | G17: ✓
B18: 19. Top up wiper washer fluid | C18: ✓ | D18: 20. Align wiper water nozzles | E18: ✓ | F18: 21. Check all radiator hoses | G18: ✓
B19: 22. Check drive belts for cracks | C19: ✓ | D19: 23. Adjust belt tensioner if needed | E19: ✓ | F19: 24. Check & adjust clutch play | G19: ✓
B20: Cabin, Lights & Electricals • 14 activities
B21: 1. Check all glass winder operations | C21: ✓ | D21: 2. Lubricate window run channels | E21: ✓ | F21: 3. Replace cabin AC filter | G21: ✓
B22: 4. Check AC cooling performance | C22: ✓ | D22: 5. AC disinfectant spray in vents | E22: ✓ | F22: 6. Inspect all front lights | G22: ✓
B23: 7. Inspect all rear lights & indicators | C23: ✓ | D23: 8. Check internal lights | E23: ✓ | F23: 9. Test all power switches | G23: ✓
B24: 10. Anti-squeak spray on hinges | C24: ✓ | D24: 11. Check door locks operation | E24: ✓ | F24: 12. Lubricate all door locks | G24: ✓
B25: 13. Onboard diagnostics scanning | C25: ✓ | D25: 14. Reset service light | E25: ✓
B26: Suspension, Wheels & Brakes • 24 activities
B27: 1. Grease all wheel nuts & bolts | C27: ✓ | D27: 2. Clean front brake pads | E27: ✓ | F27: 3. Lubricate front caliper pins | G27: ✓
B28: 4. Clean rear brake pads / liners | C28: ✓ | D28: 5. Lubricate rear caliper pins | E28: ✓ | F28: 6. Air bleed brake fluid lines | G28: ✓
B29: 7. Adjust hand brake | C29: ✓ | D29: 8. Check front wheel bearings | E29: ✓ | F29: 9. Check rear wheel bearings | G29: ✓
B30: 10. Inspect steering rack & linkages | C30: ✓ | D30: 11. Check ball joints & boots | E30: ✓ | F30: 12. Inspect front shock absorbers | G30: ✓
B31: 13. Inspect rear shock absorbers | C31: ✓ | D31: 14. Re-torque chassis nuts & bolts | E31: ✓ | F31: 15. Check all tyres for damage | G31: ✓
B32: 16. Inspect all wheel rims | C32: ✓ | D32: 17. Inspect wheel arches | E32: ✓ | F32: 18. Inspect entire underbody | G32: ✓
B33: 19. Tyre cross rotation | C33: ✓ | D33: 20. Final wheel nuts torque | E33: ✓ | F33: 21. Check & inflate all tyre pressures | G33: ✓
B34: 22. Wheel alignment | C34: ✓ | D34: 23. Wheel balancing | E34: ✓ | F34: 24. Add wheel balancing weights | G34: ✓
B35: Road Test & Final Checks • 5 activities
B36: 1. Trial drive - engine performance | C36: ✓ | D36: 2. Trial drive - brake performance | E36: ✓ | F36: 3. Trial drive - suspension check | G36: ✓
B37: 4. Final inspection post trial | C37: ✓ | D37: 5. Comprehensive report | E37: ✓
B38: Interior Detailing • 10 activities
B39: 1. Roof shampooing | C39: ✓ | D39: 2. Front seats shampooing | E39: ✓ | F39: 3. Rear seats shampooing | G39: ✓
B40: 4. Seats scrubbing & extraction | C40: ✓ | D40: 5. Floor shampooing | E40: ✓ | F40: 6. Floor scrubbing & extraction | G40: ✓
B41: 7. Door trims scrubbing | C41: ✓ | D41: 8. Door trims polishing | E41: ✓ | F41: 9. Dashboard scrubbing | G41: ✓
B42: 10. Dashboard polishing | C42: ✓
B43: Exterior Detailing • 8 activities
...

Sheet Masters
B1: PRICE LIST — Edit any yellow number when a price changes. The Estimate updates automatically.
B3: WHAT STAFF CAN PICK
B4: Service Plan | D4: Car Type | G4: Oil Grade
B5: EA Refresh | D5: Hatchback | G5: Semi-Synthetic
B6: EA Essentials | D6: Prem. Hatch / Sedan / Compact SUV | G6: Fully-Synthetic
B7: EA Pro | D7: SUV / MUV | G7: Triple-Synthetic
B8: EA 360 | D8: Premium SUV
B9: EA Elite | D9: Premium Luxury - Class 1
D10: Premium Luxury - Class 2
D11: Premium Luxury - Class 3
B14: PAYMENT MODES
B15: Payment Mode
B16: Cash
B17: UPI
B18: Card
B19: Bank Transfer
B20: Credit (Pending)
B23: ENGINE OIL (name & selling rate shown on the estimate)
B24: Oil Grade | D24: Product Name (prints on estimate) | H24: Rate / Litre
B25: Semi-Synthetic | D25: Mobil 5W-30 Semi Synthetic Engine Oil | H25: 615
B26: Fully-Synthetic | D26: Mobil Super 3000 5W-30 Fully Synthetic Engine Oil | H26: 875
B27: Triple-Synthetic | D27: Mobil 1 5W-30 Triple Synthetic Engine Oil | H27: 1500
B30: ENGINE OIL QUANTITY (litres)
B31: Car Type | F31: Refresh (L) | G31: Other Plans (L)
B32: Hatchback | F32: 1 | G32: 3.5
B33: Prem. Hatch / Sedan / Compact SUV | F33: 1 | G33: 4
B34: SUV / MUV | F34: 2 | G34: 7
B35: Premium SUV | F35: 2 | G35: 7
B36: Premium Luxury - Class 1 | F36: 2 | G36: 7
B37: Premium Luxury - Class 2 | F37: 2 | G37: 7
B38: Premium Luxury - Class 3 | F38: 2 | G38: 7
B41: PACKAGE PRICE LIST — what the customer pays (all-inclusive) ★ keep this updated
B42: Service Plan | D42: Car Type | G42: Oil Grade | H42: Price ₹
B43: EA Refresh | D43: Hatchback | G43: Semi-Synthetic | H43: 1500 | K43: =B43&"|"&D43&"|"&G43 -> EA Refresh|Hatchback|Semi-Synthetic
B44: EA Refresh | D44: Hatchback | G44: Fully-Synthetic | H44: 1800 | K44: =B44&"|"&D44&"|"&G44 -> EA Refresh|Hatchback|Fully-Synthetic
B45: EA Refresh | D45: Prem. Hatch / Sedan / Compact SUV | G45: Semi-Synthetic | H45: 2100 | K45: =B45&"|"&D45&"|"&G45 -> EA Refresh|Prem. Hatch / Sedan / Compact SUV|Semi-Synthetic
B46: EA Refresh | D46: Prem. Hatch / Sedan / Compact SUV | G46: Fully-Synthetic | H46: 2100 | K46: =B46&"|"&D46&"|"&G46 -> EA Refresh|Prem. Hatch / Sedan / Compact SUV|Fully-Synthetic
B47: EA Refresh | D47: SUV / MUV | G47: Semi-Synthetic | H47: 2750 | K47: =B47&"|"&D47&"|"&G47 -> EA Refresh|SUV / MUV|Semi-Synthetic
B48: EA Refresh | D48: SUV / MUV | G48: Fully-Synthetic | H48: 3000 | K48: =B48&"|"&D48&"|"&G48 -> EA Refresh|SUV / MUV|Fully-Synthetic
B49: EA Refresh | D49: Premium SUV | G49: Fully-Synthetic | H49: 3850 | K49: =B49&"|"&D49&"|"&G49 -> EA Refresh|Premium SUV|Fully-Synthetic
...

Sheet Line Items
B1: LINE ITEMS — what shows on the estimate for each plan. Fill the ₹ amount for every Car Type × Oil Grade.
B2: The oil line and the labour line are automatic — do NOT list them here. Labour = Package Price − everything here.
D4: Hatchback|Semi-Synthetic | E4: Hatchback|Fully-Synthetic | F4: Prem. Hatch / Sedan / Compact SUV|Semi-Synthetic | G4: Prem. Hatch / Sedan / Compact SUV|Fully-Synthetic | H4: SUV / MUV|Semi-Synthetic | I4: SUV / MUV|Fully-Synthetic | J4: Premium SUV|Fully-Synthetic | K4: Premium Luxury - Class 1|Fully-Synthetic | L4: Premium Luxury - Class 1|Triple-Synthetic | M4: Premium Luxury - Class 2|Fully-Synthetic | N4: Premium Luxury - Class 2|Triple-Synthetic | O4: Premium Luxury - Class 3|Fully-Synthetic | P4: Premium Luxury - Class 3|Triple-Synthetic
B5: Plan | C5: Item Description | D5: Hatch Semi | E5: Hatch Fully | F5: Prm HB/Sdn Semi | G5: Prm HB/Sdn Fully | H5: SUV/MUV Semi | I5: SUV/MUV Fully | J5: Prem SUV Fully | K5: PL C1 Fully | L5: PL C1 Triple | M5: PL C2 Fully | N5: PL C2 Triple | O5: PL C3 Fully | P5: PL C3 Triple
B6: EA Refresh | C6: EA Service Kit (Consumables & Lubricants Top-up) | D6: 500 | E6: 500 | F6: 500 | G6: 500 | H6: 600 | I6: 600 | J6: 600 | K6: 800 | L6: 800 | M6: 800 | N6: 800 | O6: 800 | P6: 800 | Q6: =B6&"|"&1 -> EA Refresh|1
B7: EA Essentials | C7: Oil Filter | D7: 150 | E7: 150 | F7: 250 | G7: 250 | H7: 400 | I7: 400 | J7: 500 | K7: 900 | L7: 900 | M7: 900 | N7: 900 | O7: 900 | P7: 900 | Q7: =B7&"|"&1 -> EA Essentials|1
B8: EA Essentials | C8: EA Service Kit (Consumables & Lubricants Top-up) | D8: 500 | E8: 500 | F8: 500 | G8: 500 | H8: 600 | I8: 600 | J8: 600 | K8: 800 | L8: 800 | M8: 800 | N8: 800 | O8: 800 | P8: 800 | Q8: =B8&"|"&2 -> EA Essentials|2
B9: EA Essentials | C9: Car Wash | D9: 400 | E9: 400 | F9: 400 | G9: 400 | H9: 500 | I9: 500 | J9: 500 | K9: 700 | L9: 700 | M9: 700 | N9: 700 | O9: 700 | P9: 700 | Q9: =B9&"|"&3 -> EA Essentials|3
B10: EA Pro | C10: Oil Filter | D10: 150 | E10: 150 | F10: 250 | G10: 250 | H10: 400 | I10: 400 | J10: 500 | K10: 900 | L10: 900 | M10: 900 | N10: 900 | O10: 900 | P10: 900 | Q10: =B10&"|"&1 -> EA Pro|1
B11: EA Pro | C11: EA Service Kit (Consumables & Lubricants Top-up) | D11: 500 | E11: 500 | F11: 500 | G11: 500 | H11: 600 | I11: 600 | J11: 600 | K11: 800 | L11: 800 | M11: 800 | N11: 800 | O11: 800 | P11: 800 | Q11: =B11&"|"&2 -> EA Pro|2
B12: EA Pro | C12: Brake Service, Calliper & Drum Lining Adjustment | D12: 1050 | E12: 1050 | F12: 1250 | G12: 1250 | H12: 1500 | I12: 1500 | J12: 1600 | K12: 2250 | L12: 2250 | M12: 2250 | N12: 2250 | O12: 2250 | P12: 2250 | Q12: =B12&"|"&3 -> EA Pro|3
B13: EA Pro | C13: Car Wash | D13: 400 | E13: 400 | F13: 400 | G13: 400 | H13: 500 | I13: 500 | J13: 500 | K13: 700 | L13: 700 | M13: 700 | N13: 700 | O13: 700 | P13: 700 | Q13: =B13&"|"&4 -> EA Pro|4
B14: EA 360 | C14: Oil Filter | D14: 150 | E14: 150 | F14: 250 | G14: 250 | H14: 400 | I14: 400 | J14: 500 | K14: 900 | L14: 900 | M14: 900 | N14: 900 | O14: 900 | P14: 900 | Q14: =B14&"|"&1 -> EA 360|1
B15: EA 360 | C15: EA Care Treatment | D15: 600 | E15: 600 | F15: 600 | G15: 600 | H15: 700 | I15: 700 | J15: 700 | K15: 1000 | L15: 1000 | M15: 1000 | N15: 1000 | O15: 1000 | P15: 1000 | Q15: =B15&"|"&2 -> EA 360|2
B16: EA 360 | C16: EA Service Kit (Consumables & Lubricants Top-up) | D16: 500 | E16: 500 | F16: 500 | G16: 500 | H16: 600 | I16: 600 | J16: 600 | K16: 800 | L16: 800 | M16: 800 | N16: 800 | O16: 800 | P16: 800 | Q16: =B16&"|"&3 -> EA 360|3
B17: EA 360 | C17: Air Filter | D17: 450 | E17: 450 | F17: 450 | G17: 450 | H17: 600 | I17: 600 | J17: 0 | K17: 0 | L17: 0 | M17: 0 | N17: 0 | O17: 0 | P17: 0 | Q17: =B17&"|"&4 -> EA 360|4
B18: EA 360 | C18: AC Filter | D18: 450 | E18: 450 | F18: 450 | G18: 450 | H18: 600 | I18: 600 | J18: 0 | K18: 0 | L18: 0 | M18: 0 | N18: 0 | O18: 0 | P18: 0 | Q18: =B18&"|"&5 -> EA 360|5
B19: EA 360 | C19: Wheel Alignment & Balancing | D19: 850 | E19: 850 | F19: 850 | G19: 850 | H19: 1000 | I19: 1000 | J19: 1000 | K19: 1500 | L19: 1500 | M19: 1500 | N19: 1500 | O19: 1500 | P19: 1500 | Q19: =B19&"|"&6 -> EA 360|6
B20: EA 360 | C20: Brake Service, Calliper & Drum Lining Adjustment | D20: 1050 | E20: 1050 | F20: 1250 | G20: 1250 | H20: 1500 | I20: 1500 | J20: 1600 | K20: 2250 | L20: 2250 | M20: 2250 | N20: 2250 | O20: 2250 | P20: 2250 | Q20: =B20&"|"&7 -> EA 360|7
B21: EA 360 | C21: Car Wash | D21: 400 | E21: 400 | F21: 400 | G21: 400 | H21: 500 | I21: 500 | J21: 500 | K21: 700 | L21: 700 | M21: 700 | N21: 700 | O21: 700 | P21: 700 | Q21: =B21&"|"&8 -> EA 360|8
B22: EA Elite | C22: Oil Filter | D22: 150 | E22: 150 | F22: 250 | G22: 250 | H22: 400 | I22: 400 | J22: 500 | K22: 900 | L22: 900 | M22: 900 | N22: 900 | O22: 900 | P22: 900 | Q22: =B22&"|"&1 -> EA Elite|1
B23: EA Elite | C23: EA Care Treatment | D23: 600 | E23: 600 | F23: 600 | G23: 600 | H23: 700 | I23: 700 | J23: 700 | K23: 1000 | L23: 1000 | M23: 1000 | N23: 1000 | O23: 1000 | P23: 1000 | Q23: =B23&"|"&2 -> EA Elite|2
B24: EA Elite | C24: EA Service Kit (Consumables & Lubricants Top-up) | D24: 500 | E24: 500 | F24: 500 | G24: 500 | H24: 600 | I24: 600 | J24: 600 | K24: 800 | L24: 800 | M24: 800 | N24: 800 | O24: 800 | P24: 800 | Q24: =B24&"|"&3 -> EA Elite|3
B25: EA Elite | C25: Air Filter | D25: 450 | E25: 450 | F25: 450 | G25: 450 | H25: 600 | I25: 600 | J25: 0 | K25: 0 | L25: 0 | M25: 0 | N25: 0 | O25: 0 | P25: 0 | Q25: =B25&"|"&4 -> EA Elite|4
B26: EA Elite | C26: AC Filter | D26: 450 | E26: 450 | F26: 450 | G26: 450 | H26: 600 | I26: 600 | J26: 0 | K26: 0 | L26: 0 | M26: 0 | N26: 0 | O26: 0 | P26: 0 | Q26: =B26&"|"&5 -> EA Elite|5
B27: EA Elite | C27: Interior Anti-Bacterial Treatment | D27: 2124 | E27: 2124 | F27: 2478 | G27: 2478 | H27: 3540 | I27: 3540 | J27: 3540 | K27: 4130 | L27: 4130 | M27: 4130 | N27: 4130 | O27: 4130 | P27: 4130 | Q27: =B27&"|"&6 -> EA Elite|6
B28: EA Elite | C28: Exterior Treatment | D28: 3570 | E28: 3570 | F28: 4425 | G28: 4425 | H28: 4720 | I28: 4720 | J28: 4720 | K28: 5605 | L28: 5605 | M28: 5605 | N28: 5605 | O28: 5605 | P28: 5605 | Q28: =B28&"|"&7 -> EA Elite|7
B29: EA Elite | C29: Wheel Alignment & Balancing | D29: 850 | E29: 850 | F29: 850 | G29: 850 | H29: 1000 | I29: 1000 | J29: 1000 | K29: 1500 | L29: 1500 | M29: 1500 | N29: 1500 | O29: 1500 | P29: 1500 | Q29: =B29&"|"&8 -> EA Elite|8
B30: EA Elite | C30: Brake Service, Calliper & Drum Lining Adjustment | D30: 1050 | E30: 1050 | F30: 1250 | G30: 1250 | H30: 1500 | I30: 1500 | J30: 1600 | K30: 2250 | L30: 2250 | M30: 2250 | N30: 2250 | O30: 2250 | P30: 2250 | Q30: =B30&"|"&9 -> EA Elite|9
B31: EA Elite | C31: Car Wash | D31: 400 | E31: 400 | F31: 400 | G31: 400 | H31: 500 | I31: 500 | J31: 500 | K31: 700 | L31: 700 | M31: 700 | N31: 700 | O31: 700 | P31: 700 | Q31: =B31&"|"&10 -> EA Elite|10
B33: Legend: Prm HB/Sdn = Prem. Hatch / Sedan / Compact SUV • PL C1/2/3 = Premium Luxury Class 1/2/3 • grey = not offered

Sheet How to Use
B2: EXPRESS AUTOCARE — How to Make an Estimate
B4: For the person making estimates — 6 steps on the 'Estimate' tab:
B5: 1. Type Customer Name, Car Model, Reg No and KMS at the top.
B6: 2. Pick the Service Plan from the drop-down.
B7: 3. Pick the Car Type from the drop-down.
B8: 4. Pick the Oil Grade: Regular cars → Semi or Fully • Premium SUV → Fully • Premium Luxury → Fully or Triple.
B9: 5. Everything fills in: the oil line, the included items, the Labour line and the package total.
B10: • The Labour line sits right after the items and adjusts by itself so the package always totals correctly.
B11: • To add an extra item INSIDE the package, type its Qty & Rate in the cream rows just above the Labour line —
B12: the amount fills in and the Labour line reduces so the package total stays the same.
B13: • Change the oil litres and the Labour line re-balances on its own.
B14: 6. Extra work billed ON TOP goes in 'Additional Parts & Labour' (type Qty & Rate).
... B35: • Staff use the 'Estimate' tab and the matching report tab. Only the owner edits 'Masters' and 'Line Items'.

Sheet Ref
A1: Zero
A2: One
A3: Two
A4: Three
A5: Four
A6: Five
A7: Six
A8: Seven
A9: Eight
A10: Nine
A11: Ten
A12: Eleven
... A100: Ninety Nine
