Workbook

Sheet How to use
B2: Express Autocare ERP — Test checklist (v2)
B3: 276 checks covering every module and flow (Phases 1–11: job cards to delivery, parts and purchases, billing, pickup / drop / home service, attendance, payroll, accounts, CRM, WhatsApp inbox and Interakt, customer app, fleet cabs and drivers, settings, roles, phones), grouped into journeys that follow a car and a staff member through the system.
B5: How to work | C5: Go through the Checklist sheet top to bottom (Day column = suggested day). Do the step as the role in "Who", compare with "Expected result". Use the filter arrows to see one journey, one role or only Critical checks.
B6: Fill in (yellow) | C6: Status, Tested on, Notes and Issue ID on the Checklist sheet; every column on the Issues sheet. Everything else is fixed.
B7: Status values | C7: Pass · Fail · Blocked (could not test because of another problem) · N/A (not used by us, e.g. Interakt not bought yet). Leave empty = not tested yet.
B8: Priority | C8: Critical = money, data or a whole flow; test these first · High = an everyday screen · Normal = the rest.
B9: When something fails | C9: Set Status = Fail, add a row on the Issues sheet (ID I-001, I-002 …), and put that ID in the Issue ID column. Don't stop to report: send the Issues sheet after the week.
B10: Priority (Issues) | C10: Must fix = wrong numbers, data lost, blocks work · Should fix = works but confusing or slow · Nice to have = an idea.
B11: Progress | C11: The Summary sheet counts Pass / Fail / Blocked / not tested per journey, per priority and per role by itself.
B12: Test data | C12: Use the TEST copy, never live data. Demo logins: admin@ / manager@ / advisor@ / tech1@ / tech2@ / backoffice@ / parts@ / driver@ / marketing@expressautocare.in, password: password. For "Customer" and "Driver (fleet)" use spare phones with their own numbers.
B13: Don't wait for time | C13: php artisan crm:run · crm:daily · crm:interakt-sync · customerapp:reminders · fleet:daily · hr:close-attendance · hr:tracking run the timed jobs now. Keep php artisan schedule:work running anyway.
B14: WhatsApp / Interakt | C14: Section 2b needs an Interakt account (Growth or above; incoming chats need its higher plan). Without one, test the Share-links rows and mark the rest N/A.
B15: Phones | C15: Use the https tunnel address (Installation Guide §3). Location, camera and app notifications do not work on plain http on phones.
B16: Help | C16: User Manual (docs/EAERP_User_Manual.pdf, v3) for how each screen works; Quick Guide; App Installation & Play Store Guide for the phones.
B18: Legend
B19: You fill in | C19: Yellow cells
B20: Pass | C20: Row colour when the Status is Pass
B21: Fail | C21: Row colour when the Status is Fail
B22: Blocked | C22: Row colour when the Status is Blocked
B23: N/A | C23: Row colour when the Status is N/A
B25: Example | C25: A filled-in row: Status = Fail · Tested on = 23-Oct · Notes = "Bell came but the lead was given to Ravi who is on leave" · Issue ID = I-004

Sheet Summary
A1: Express Autocare ERP — test progress
A2: All counts update by themselves from the Status column of the Checklist sheet. Nothing to type here.
A4: Journey | B4: Checks | C4: Pass | D4: Fail | E4: Blocked | F4: N/A | G4: Not tested | H4: Done %
A5: 0. Setup and signing in | B5: =COUNTIF(Checklist!$C$2:$C$277,A5) -> 17 | C5: =COUNTIFS(Checklist!$C$2:$C$277,A5,Checklist!$J$2:$J$277,"Pass") -> 0 | D5: =COUNTIFS(Checklist!$C$2:$C$277,A5,Checklist!$J$2:$J$277,"Fail") -> 0 | E5: =COUNTIFS(Checklist!$C$2:$C$277,A5,Checklist!$J$2:$J$277,"Blocked") -> 0 | F5: =COUNTIFS(Checklist!$C$2:$C$277,A5,Checklist!$J$2:$J$277,"N/A") -> 0 | G5: =B5-SUM(C5:F5) -> 17 | H5: =IF(B5=0,0,(B5-G5)/B5) -> 0
A6: 1. Drive-in service-plan job (Purchases & Stock ON) | B6: =COUNTIF(Checklist!$C$2:$C$277,A6) -> 29 | C6: =COUNTIFS(Checklist!$C$2:$C$277,A6,Checklist!$J$2:$J$277,"Pass") -> 0 | D6: =COUNTIFS(Checklist!$C$2:$C$277,A6,Checklist!$J$2:$J$277,"Fail") -> 0 | E6: =COUNTIFS(Checklist!$C$2:$C$277,A6,Checklist!$J$2:$J$277,"Blocked") -> 0 | F6: =COUNTIFS(Checklist!$C$2:$C$277,A6,Checklist!$J$2:$J$277,"N/A") -> 0 | G6: =B6-SUM(C6:F6) -> 29 | H6: =IF(B6=0,0,(B6-G6)/B6) -> 0
A7: 1b. Same job with Purchases & Stock OFF | B7: =COUNTIF(Checklist!$C$2:$C$277,A7) -> 4 | C7: =COUNTIFS(Checklist!$C$2:$C$277,A7,Checklist!$J$2:$J$277,"Pass") -> 0 | D7: =COUNTIFS(Checklist!$C$2:$C$277,A7,Checklist!$J$2:$J$277,"Fail") -> 0 | E7: =COUNTIFS(Checklist!$C$2:$C$277,A7,Checklist!$J$2:$J$277,"Blocked") -> 0 | F7: =COUNTIFS(Checklist!$C$2:$C$277,A7,Checklist!$J$2:$J$277,"N/A") -> 0 | G7: =B7-SUM(C7:F7) -> 4 | H7: =IF(B7=0,0,(B7-G7)/B7) -> 0
A8: 1c. Repair jobs, estimates and job-card details | B8: =COUNTIF(Checklist!$C$2:$C$277,A8) -> 19 | C8: =COUNTIFS(Checklist!$C$2:$C$277,A8,Checklist!$J$2:$J$277,"Pass") -> 0 | D8: =COUNTIFS(Checklist!$C$2:$C$277,A8,Checklist!$J$2:$J$277,"Fail") -> 0 | E8: =COUNTIFS(Checklist!$C$2:$C$277,A8,Checklist!$J$2:$J$277,"Blocked") -> 0 | F8: =COUNTIFS(Checklist!$C$2:$C$277,A8,Checklist!$J$2:$J$277,"N/A") -> 0 | G8: =B8-SUM(C8:F8) -> 19 | H8: =IF(B8=0,0,(B8-G8)/B8) -> 0
A9: 2. Lead to booking (CRM) | B9: =COUNTIF(Checklist!$C$2:$C$277,A9) -> 22 | C9: =COUNTIFS(Checklist!$C$2:$C$277,A9,Checklist!$J$2:$J$277,"Pass") -> 0 | D9: =COUNTIFS(Checklist!$C$2:$C$277,A9,Checklist!$J$2:$J$277,"Fail") -> 0 | E9: =COUNTIFS(Checklist!$C$2:$C$277,A9,Checklist!$J$2:$J$277,"Blocked") -> 0 | F9: =COUNTIFS(Checklist!$C$2:$C$277,A9,Checklist!$J$2:$J$277,"N/A") -> 0 | G9: =B9-SUM(C9:F9) -> 22 | H9: =IF(B9=0,0,(B9-G9)/B9) -> 0
A10: 2b. WhatsApp inbox and Interakt (CRM) | B10: =COUNTIF(Checklist!$C$2:$C$277,A10) -> 37 | C10: =COUNTIFS(Checklist!$C$2:$C$277,A10,Checklist!$J$2:$J$277,"Pass") -> 0 | D10: =COUNTIFS(Checklist!$C$2:$C$277,A10,Checklist!$J$2:$J$277,"Fail") -> 0 | E10: =COUNTIFS(Checklist!$C$2:$C$277,A10,Checklist!$J$2:$J$277,"Blocked") -> 0 | F10: =COUNTIFS(Checklist!$C$2:$C$277,A10,Checklist!$J$2:$J$277,"N/A") -> 0 | G10: =B10-SUM(C10:F10) -> 37 | H10: =IF(B10=0,0,(B10-G10)/B10) -> 0
A11: 3. Pickup & drop, home service, live location | B11: =COUNTIF(Checklist!$C$2:$C$277,A11) -> 15 | C11: =COUNTIFS(Checklist!$C$2:$C$277,A11,Checklist!$J$2:$J$277,"Pass") -> 0 | D11: =COUNTIFS(Checklist!$C$2:$C$277,A11,Checklist!$J$2:$J$277,"Fail") -> 0 | E11: =COUNTIFS(Checklist!$C$2:$C$277,A11,Checklist!$J$2:$J$277,"Blocked") -> 0 | F11: =COUNTIFS(Checklist!$C$2:$C$277,A11,Checklist!$J$2:$J$277,"N/A") -> 0 | G11: =B11-SUM(C11:F11) -> 15 | H11: =IF(B11=0,0,(B11-G11)/B11) -> 0
A12: 4. Accident / body shop | B12: =COUNTIF(Checklist!$C$2:$C$277,A12) -> 5 | C12: =COUNTIFS(Checklist!$C$2:$C$277,A12,Checklist!$J$2:$J$277,"Pass") -> 0 | D12: =COUNTIFS(Checklist!$C$2:$C$277,A12,Checklist!$J$2:$J$277,"Fail") -> 0 | E12: =COUNTIFS(Checklist!$C$2:$C$277,A12,Checklist!$J$2:$J$277,"Blocked") -> 0 | F12: =COUNTIFS(Checklist!$C$2:$C$277,A12,Checklist!$J$2:$J$277,"N/A") -> 0 | G12: =B12-SUM(C12:F12) -> 5 | H12: =IF(B12=0,0,(B12-G12)/B12) -> 0
A13: 5. A staff week (attendance, leave, live map) | B13: =COUNTIF(Checklist!$C$2:$C$277,A13) -> 15 | C13: =COUNTIFS(Checklist!$C$2:$C$277,A13,Checklist!$J$2:$J$277,"Pass") -> 0 | D13: =COUNTIFS(Checklist!$C$2:$C$277,A13,Checklist!$J$2:$J$277,"Fail") -> 0 | E13: =COUNTIFS(Checklist!$C$2:$C$277,A13,Checklist!$J$2:$J$277,"Blocked") -> 0 | F13: =COUNTIFS(Checklist!$C$2:$C$277,A13,Checklist!$J$2:$J$277,"N/A") -> 0 | G13: =B13-SUM(C13:F13) -> 15 | H13: =IF(B13=0,0,(B13-G13)/B13) -> 0
A14: 6. Month end: payroll, accounts, dashboard | B14: =COUNTIF(Checklist!$C$2:$C$277,A14) -> 14 | C14: =COUNTIFS(Checklist!$C$2:$C$277,A14,Checklist!$J$2:$J$277,"Pass") -> 0 | D14: =COUNTIFS(Checklist!$C$2:$C$277,A14,Checklist!$J$2:$J$277,"Fail") -> 0 | E14: =COUNTIFS(Checklist!$C$2:$C$277,A14,Checklist!$J$2:$J$277,"Blocked") -> 0 | F14: =COUNTIFS(Checklist!$C$2:$C$277,A14,Checklist!$J$2:$J$277,"N/A") -> 0 | G14: =B14-SUM(C14:F14) -> 14 | H14: =IF(B14=0,0,(B14-G14)/B14) -> 0
A15: 7. Customer app tour | B15: =COUNTIF(Checklist!$C$2:$C$277,A15) -> 21 | C15: =COUNTIFS(Checklist!$C$2:$C$277,A15,Checklist!$J$2:$J$277,"Pass") -> 0 | D15: =COUNTIFS(Checklist!$C$2:$C$277,A15,Checklist!$J$2:$J$277,"Fail") -> 0 | E15: =COUNTIFS(Checklist!$C$2:$C$277,A15,Checklist!$J$2:$J$277,"Blocked") -> 0 | F15: =COUNTIFS(Checklist!$C$2:$C$277,A15,Checklist!$J$2:$J$277,"N/A") -> 0 | G15: =B15-SUM(C15:F15) -> 21 | H15: =IF(B15=0,0,(B15-G15)/B15) -> 0
A16: 7b. Fleet cabs and drivers | B16: =COUNTIF(Checklist!$C$2:$C$277,A16) -> 24 | C16: =COUNTIFS(Checklist!$C$2:$C$277,A16,Checklist!$J$2:$J$277,"Pass") -> 0 | D16: =COUNTIFS(Checklist!$C$2:$C$277,A16,Checklist!$J$2:$J$277,"Fail") -> 0 | E16: =COUNTIFS(Checklist!$C$2:$C$277,A16,Checklist!$J$2:$J$277,"Blocked") -> 0 | F16: =COUNTIFS(Checklist!$C$2:$C$277,A16,Checklist!$J$2:$J$277,"N/A") -> 0 | G16: =B16-SUM(C16:F16) -> 24 | H16: =IF(B16=0,0,(B16-G16)/B16) -> 0
... A20: 11. Phones and the Android apps | B20: =COUNTIF(Checklist!$C$2:$C$277,A20) -> 7 | C20: =COUNTIFS(Checklist!$C$2:$C$277,A20,Checklist!$J$2:$J$277,"Pass") -> 0 | D20: =COUNTIFS(Checklist!$C$2:$C$277,A20,Checklist!$J$2:$J$277,"Fail") -> 0 | E20: =COUNTIFS(Checklist!$C$2:$C$277,A20,Checklist!$J$2:$J$277,"Blocked") -> 0 | F20: =COUNTIFS(Checklist!$C$2:$C$277,A20,Checklist!$J$2:$J$277,"N/A") -> 0 | G20: =B20-SUM(C20:F20) -> 7 | H20: =IF(B20=0,0,(B20-G20)/B20) -> 0
A21: Total | B21: =SUM(B5:B20) -> 276 | C21: =SUM(C5:C20) -> 0 | D21: =SUM(D5:D20) -> 0 | E21: =SUM(E5:E20) -> 0 | F21: =SUM(F5:F20) -> 0 | G21: =SUM(G5:G20) -> 276 | H21: =IF(B21=0,0,(B21-G21)/B21) -> 0
A23: By priority
A24: Priority | B24: Checks | C24: Pass | D24: Fail | E24: Blocked | F24: N/A | G24: Not tested | H24: Done %
A25: Critical | B25: =COUNTIF(Checklist!$I$2:$I$277,A25) -> 63 | C25: =COUNTIFS(Checklist!$I$2:$I$277,A25,Checklist!$J$2:$J$277,"Pass") -> 0 | D25: =COUNTIFS(Checklist!$I$2:$I$277,A25,Checklist!$J$2:$J$277,"Fail") -> 0 | E25: =COUNTIFS(Checklist!$I$2:$I$277,A25,Checklist!$J$2:$J$277,"Blocked") -> 0 | F25: =COUNTIFS(Checklist!$I$2:$I$277,A25,Checklist!$J$2:$J$277,"N/A") -> 0 | G25: =B25-SUM(C25:F25) -> 63 | H25: =IF(B25=0,0,(B25-G25)/B25) -> 0
A26: High | B26: =COUNTIF(Checklist!$I$2:$I$277,A26) -> 145 | C26: =COUNTIFS(Checklist!$I$2:$I$277,A26,Checklist!$J$2:$J$277,"Pass") -> 0 | D26: =COUNTIFS(Checklist!$I$2:$I$277,A26,Checklist!$J$2:$J$277,"Fail") -> 0 | E26: =COUNTIFS(Checklist!$I$2:$I$277,A26,Checklist!$J$2:$J$277,"Blocked") -> 0 | F26: =COUNTIFS(Checklist!$I$2:$I$277,A26,Checklist!$J$2:$J$277,"N/A") -> 0 | G26: =B26-SUM(C26:F26) -> 145 | H26: =IF(B26=0,0,(B26-G26)/B26) -> 0
A27: Normal | B27: =COUNTIF(Checklist!$I$2:$I$277,A27) -> 68 | C27: =COUNTIFS(Checklist!$I$2:$I$277,A27,Checklist!$J$2:$J$277,"Pass") -> 0 | D27: =COUNTIFS(Checklist!$I$2:$I$277,A27,Checklist!$J$2:$J$277,"Fail") -> 0 | E27: =COUNTIFS(Checklist!$I$2:$I$277,A27,Checklist!$J$2:$J$277,"Blocked") -> 0 | F27: =COUNTIFS(Checklist!$I$2:$I$277,A27,Checklist!$J$2:$J$277,"N/A") -> 0 | G27: =B27-SUM(C27:F27) -> 68 | H27: =IF(B27=0,0,(B27-G27)/B27) -> 0
A28: Critical checks failing or blocked (fix these first) | B28: =D25+E25 -> 0
A30: By role (Who)
A31: Who | B31: Checks | C31: Pass | D31: Fail | E31: Blocked | F31: N/A | G31: Not tested | H31: Done %
A32: Owner | B32: =COUNTIF(Checklist!$E$2:$E$277,A32) -> 71 | C32: =COUNTIFS(Checklist!$E$2:$E$277,A32,Checklist!$J$2:$J$277,"Pass") -> 0 | D32: =COUNTIFS(Checklist!$E$2:$E$277,A32,Checklist!$J$2:$J$277,"Fail") -> 0 | E32: =COUNTIFS(Checklist!$E$2:$E$277,A32,Checklist!$J$2:$J$277,"Blocked") -> 0 | F32: =COUNTIFS(Checklist!$E$2:$E$277,A32,Checklist!$J$2:$J$277,"N/A") -> 0 | G32: =B32-SUM(C32:F32) -> 71 | H32: =IF(B32=0,0,(B32-G32)/B32) -> 0
A33: Everyone | B33: =COUNTIF(Checklist!$E$2:$E$277,A33) -> 8 | C33: =COUNTIFS(Checklist!$E$2:$E$277,A33,Checklist!$J$2:$J$277,"Pass") -> 0 | D33: =COUNTIFS(Checklist!$E$2:$E$277,A33,Checklist!$J$2:$J$277,"Fail") -> 0 | E33: =COUNTIFS(Checklist!$E$2:$E$277,A33,Checklist!$J$2:$J$277,"Blocked") -> 0 | F33: =COUNTIFS(Checklist!$E$2:$E$277,A33,Checklist!$J$2:$J$277,"N/A") -> 0 | G33: =B33-SUM(C33:F33) -> 8 | H33: =IF(B33=0,0,(B33-G33)/B33) -> 0
A34: Advisor | B34: =COUNTIF(Checklist!$E$2:$E$277,A34) -> 45 | C34: =COUNTIFS(Checklist!$E$2:$E$277,A34,Checklist!$J$2:$J$277,"Pass") -> 0 | D34: =COUNTIFS(Checklist!$E$2:$E$277,A34,Checklist!$J$2:$J$277,"Fail") -> 0 | E34: =COUNTIFS(Checklist!$E$2:$E$277,A34,Checklist!$J$2:$J$277,"Blocked") -> 0 | F34: =COUNTIFS(Checklist!$E$2:$E$277,A34,Checklist!$J$2:$J$277,"N/A") -> 0 | G34: =B34-SUM(C34:F34) -> 45 | H34: =IF(B34=0,0,(B34-G34)/B34) -> 0
A35: Technician | B35: =COUNTIF(Checklist!$E$2:$E$277,A35) -> 15 | C35: =COUNTIFS(Checklist!$E$2:$E$277,A35,Checklist!$J$2:$J$277,"Pass") -> 0 | D35: =COUNTIFS(Checklist!$E$2:$E$277,A35,Checklist!$J$2:$J$277,"Fail") -> 0 | E35: =COUNTIFS(Checklist!$E$2:$E$277,A35,Checklist!$J$2:$J$277,"Blocked") -> 0 | F35: =COUNTIFS(Checklist!$E$2:$E$277,A35,Checklist!$J$2:$J$277,"N/A") -> 0 | G35: =B35-SUM(C35:F35) -> 15 | H35: =IF(B35=0,0,(B35-G35)/B35) -> 0
A36: Parts coordinator | B36: =COUNTIF(Checklist!$E$2:$E$277,A36) -> 5 | C36: =COUNTIFS(Checklist!$E$2:$E$277,A36,Checklist!$J$2:$J$277,"Pass") -> 0 | D36: =COUNTIFS(Checklist!$E$2:$E$277,A36,Checklist!$J$2:$J$277,"Fail") -> 0 | E36: =COUNTIFS(Checklist!$E$2:$E$277,A36,Checklist!$J$2:$J$277,"Blocked") -> 0 | F36: =COUNTIFS(Checklist!$E$2:$E$277,A36,Checklist!$J$2:$J$277,"N/A") -> 0 | G36: =B36-SUM(C36:F36) -> 5 | H36: =IF(B36=0,0,(B36-G36)/B36) -> 0
A37: Customer | B37: =COUNTIF(Checklist!$E$2:$E$277,A37) -> 49 | C37: =COUNTIFS(Checklist!$E$2:$E$277,A37,Checklist!$J$2:$J$277,"Pass") -> 0 | D37: =COUNTIFS(Checklist!$E$2:$E$277,A37,Checklist!$J$2:$J$277,"Fail") -> 0 | E37: =COUNTIFS(Checklist!$E$2:$E$277,A37,Checklist!$J$2:$J$277,"Blocked") -> 0 | F37: =COUNTIFS(Checklist!$E$2:$E$277,A37,Checklist!$J$2:$J$277,"N/A") -> 0 | G37: =B37-SUM(C37:F37) -> 49 | H37: =IF(B37=0,0,(B37-G37)/B37) -> 0
A38: Manager | B38: =COUNTIF(Checklist!$E$2:$E$277,A38) -> 14 | C38: =COUNTIFS(Checklist!$E$2:$E$277,A38,Checklist!$J$2:$J$277,"Pass") -> 0 | D38: =COUNTIFS(Checklist!$E$2:$E$277,A38,Checklist!$J$2:$J$277,"Fail") -> 0 | E38: =COUNTIFS(Checklist!$E$2:$E$277,A38,Checklist!$J$2:$J$277,"Blocked") -> 0 | F38: =COUNTIFS(Checklist!$E$2:$E$277,A38,Checklist!$J$2:$J$277,"N/A") -> 0 | G38: =B38-SUM(C38:F38) -> 14 | H38: =IF(B38=0,0,(B38-G38)/B38) -> 0
A39: Back office | B39: =COUNTIF(Checklist!$E$2:$E$277,A39) -> 21 | C39: =COUNTIFS(Checklist!$E$2:$E$277,A39,Checklist!$J$2:$J$277,"Pass") -> 0 | D39: =COUNTIFS(Checklist!$E$2:$E$277,A39,Checklist!$J$2:$J$277,"Fail") -> 0 | E39: =COUNTIFS(Checklist!$E$2:$E$277,A39,Checklist!$J$2:$J$277,"Blocked") -> 0 | F39: =COUNTIFS(Checklist!$E$2:$E$277,A39,Checklist!$J$2:$J$277,"N/A") -> 0 | G39: =B39-SUM(C39:F39) -> 21 | H39: =IF(B39=0,0,(B39-G39)/B39) -> 0
A40: Marketing | B40: =COUNTIF(Checklist!$E$2:$E$277,A40) -> 17 | C40: =COUNTIFS(Checklist!$E$2:$E$277,A40,Checklist!$J$2:$J$277,"Pass") -> 0 | D40: =COUNTIFS(Checklist!$E$2:$E$277,A40,Checklist!$J$2:$J$277,"Fail") -> 0 | E40: =COUNTIFS(Checklist!$E$2:$E$277,A40,Checklist!$J$2:$J$277,"Blocked") -> 0 | F40: =COUNTIFS(Checklist!$E$2:$E$277,A40,Checklist!$J$2:$J$277,"N/A") -> 0 | G40: =B40-SUM(C40:F40) -> 17 | H40: =IF(B40=0,0,(B40-G40)/B40) -> 0
A41: Driver | B41: =COUNTIF(Checklist!$E$2:$E$277,A41) -> 12 | C41: =COUNTIFS(Checklist!$E$2:$E$277,A41,Checklist!$J$2:$J$277,"Pass") -> 0 | D41: =COUNTIFS(Checklist!$E$2:$E$277,A41,Checklist!$J$2:$J$277,"Fail") -> 0 | E41: =COUNTIFS(Checklist!$E$2:$E$277,A41,Checklist!$J$2:$J$277,"Blocked") -> 0 | F41: =COUNTIFS(Checklist!$E$2:$E$277,A41,Checklist!$J$2:$J$277,"N/A") -> 0 | G41: =B41-SUM(C41:F41) -> 12 | H41: =IF(B41=0,0,(B41-G41)/B41) -> 0
A42: Home technician | B42: =COUNTIF(Checklist!$E$2:$E$277,A42) -> 1 | C42: =COUNTIFS(Checklist!$E$2:$E$277,A42,Checklist!$J$2:$J$277,"Pass") -> 0 | D42: =COUNTIFS(Checklist!$E$2:$E$277,A42,Checklist!$J$2:$J$277,"Fail") -> 0 | E42: =COUNTIFS(Checklist!$E$2:$E$277,A42,Checklist!$J$2:$J$277,"Blocked") -> 0 | F42: =COUNTIFS(Checklist!$E$2:$E$277,A42,Checklist!$J$2:$J$277,"N/A") -> 0 | G42: =B42-SUM(C42:F42) -> 1 | H42: =IF(B42=0,0,(B42-G42)/B42) -> 0
A43: Body shop advisor | B43: =COUNTIF(Checklist!$E$2:$E$277,A43) -> 1 | C43: =COUNTIFS(Checklist!$E$2:$E$277,A43,Checklist!$J$2:$J$277,"Pass") -> 0 | D43: =COUNTIFS(Checklist!$E$2:$E$277,A43,Checklist!$J$2:$J$277,"Fail") -> 0 | E43: =COUNTIFS(Checklist!$E$2:$E$277,A43,Checklist!$J$2:$J$277,"Blocked") -> 0 | F43: =COUNTIFS(Checklist!$E$2:$E$277,A43,Checklist!$J$2:$J$277,"N/A") -> 0 | G43: =B43-SUM(C43:F43) -> 1 | H43: =IF(B43=0,0,(B43-G43)/B43) -> 0
... A48: Body shop manager / advisor / technician | B48: =COUNTIF(Checklist!$E$2:$E$277,A48) -> 1 | C48: =COUNTIFS(Checklist!$E$2:$E$277,A48,Checklist!$J$2:$J$277,"Pass") -> 0 | D48: =COUNTIFS(Checklist!$E$2:$E$277,A48,Checklist!$J$2:$J$277,"Fail") -> 0 | E48: =COUNTIFS(Checklist!$E$2:$E$277,A48,Checklist!$J$2:$J$277,"Blocked") -> 0 | F48: =COUNTIFS(Checklist!$E$2:$E$277,A48,Checklist!$J$2:$J$277,"N/A") -> 0 | G48: =B48-SUM(C48:F48) -> 1 | H48: =IF(B48=0,0,(B48-G48)/B48) -> 0
A50: Issues
A51: Open issues (Must fix) | B51: =COUNTIFS(Issues!$J$3:$J$152,"Must fix",Issues!$K$3:$K$152,"Open") -> 0
...

Sheet Checklist
A1: ID | B1: Day | C1: Section | D1: Module | E1: Who | F1: What to do | G1: Expected result | H1: Where | I1: Priority | J1: Status | K1: Tested on | L1: Notes | M1: Issue ID
A2: 0.01 | B2: Day 1 | C2: 0. Setup and signing in | D2: Setup | E2: Owner | F2: Use a TEST copy of the database (e.g. test_eaerp_demo or a fresh copy), never live data | G2: You can create and cancel records freely | H2: .env DB_DATABASE | I2: Critical
A3: 0.02 | B3: Day 1 | C3: 0. Setup and signing in | D3: Setup | E3: Owner | F3: npm run build, delete public\hot, start: php artisan serve --host 0.0.0.0 --port 8000 | G3: Sign-in page opens on a phone on the same Wi-Fi | H3: Installation Guide §2 | I3: Critical
A4: 0.03 | B4: Day 1 | C4: 0. Setup and signing in | D4: Setup | E4: Owner | F4: Start the HTTPS tunnel (cloudflared) and set Settings › App Address & Customer App › Public address + APP_URL | G4: Phones open the https address with a padlock; photos load | H4: Installation Guide §3 | I4: High
A5: 0.04 | B5: Day 1 | C5: 0. Setup and signing in | D5: Setup | E5: Owner | F5: Keep php artisan schedule:work running in a second window | G5: Scheduled jobs run (CRM every 15 min, reminders, location clean-up, attendance close, fleet:daily) | H5: Command window | I5: High
A6: 0.05 | B6: Day 1 | C6: 0. Setup and signing in | D6: Setup | E6: Owner | F6: Check there is one login per role (Settings › Users & App Logins); create Body shop manager / advisor / technician and Marketing users if missing | G6: Every role can sign in | H6: Settings › Users | I6: Critical
A7: 0.06 | B7: Day 1 | C7: 0. Setup and signing in | D7: Setup | E7: Owner | F7: Settings › Branches: workshop location (lat/lng), radius, weekly off for each branch | G7: Punching works only inside the radius | H7: Settings › Branches | I7: High
A8: 0.07 | B8: Day 1 | C8: 0. Setup and signing in | D8: Setup | E8: Owner | F8: Settings › App Address & Customer App: UPI ID, payee name, helpline, code validity, phone notifications; Fleet cabs: driver limit ₹2,000, warning 500 km | G8: Saved; QR codes shown | H8: Settings › App Address & Customer App | I8: High
A9: 0.08 | B9: Day 1 | C9: 0. Setup and signing in | D9: Setup | E9: Owner | F9: Settings › Modules: every module ON (Purchases & stock, Accounts, CRM, Attendance & payroll, Customer app, Fleet cabs & drivers) | G9: All menus visible | H9: Settings › Modules | I9: Critical
A10: 0.09 | B10: Day 1 | C10: 0. Setup and signing in | D10: Setup | E10: Owner | F10: Install the staff APK on a driver phone and a technician phone (enter the tunnel address) | G10: EA Workshop app signs in | H10: Installation Guide §4 | I10: Normal
A11: 0.10 | B11: Day 1 | C11: 0. Setup and signing in | D11: Setup | E11: Owner | F11: Optional: Settings › AI Assistant: add an Anthropic key, budget ₹200, switch on | G11: Assistant available in the customer app | H11: Settings › AI Assistant | I11: Normal
A12: 0.11 | B12: Day 1 | C12: 0. Setup and signing in | D12: Setup | E12: Owner | F12: Optional: Interakt test account (Growth or above): API key, webhook URL and secret key ready | G12: Needed for section 2b; otherwise mark 2b rows N/A where they need Interakt | H12: Interakt › Developer Settings | I12: Normal
A13: 0.12 | B13: Day 1 | C13: 0. Setup and signing in | D13: Sign-in | E13: Everyone | F13: Sign in with e-mail + password, then sign out; sign in with a phone-only login (mobile number) | G13: Both work; signing out returns to the sign-in page | H13: /login | I13: Critical
... A277: 11.07 | B277: Day 6 | C277: 11. Phones and the Android apps | D277: PWA | E277: Advisor | F277: Install the staff web app on a phone (Add to Home screen) | G277: Opens full screen; bottom bar + More | H277: Phone browser | I277: Normal

Sheet Issues
A1: Issue ID | B1: Date | C1: Checklist ID | D1: Screen | E1: Role | F1: What I did | G1: What I expected | H1: What happened | I1: Screenshot file | J1: Priority | K1: Status | L1: Fixed in
A2: I-000 (example) | B2: 19-Oct | C2: 1.21 | D2: Job card › Billing | E2: Back office | F2: Clicked Make bill after final QC | G2: Proforma created | H2: Error "Send the estimate first" although it was sent | I2: IMG_2041.jpg | J2: Must fix | K2: Open
A3: I-001
A4: I-002
A5: I-003
A6: I-004
A7: I-005
A8: I-006
A9: I-007
A10: I-008
A11: I-009
A12: I-010
A13: I-011
A14: I-012
... A152: I-150
